{
  try {
    run2();
  }
 catch (  Exception e) {
    _log.error("Error starting",e);
  }
}
